<?xml version="1.0"?>
<robot xmlns:xacro="http://www.ros.org/wiki/xacro" name="xiaor_geek_bot">

  <!-- Include inertial macros -->
  <xacro:include filename="inertial_macros.xacro"/>

  <!-- Materials -->
  <material name="black"><color rgba="0 0 0 1"/></material>
  <material name="white"><color rgba="1 1 1 1"/></material>
  <material name="silver"><color rgba="0.75 0.75 0.75 1"/></material>
  <material name="blue"><color rgba="0.2 0.2 1 1"/></material>
  <material name="green"><color rgba="0.2 1 0.2 1"/></material>
  <material name="red"><color rgba="1 0.1 0.1 1"/></material>

  <!-- Base link -->
  <link name="base_link"/>

  <!-- Chassis -->
  <joint name="chassis_joint" type="fixed">
    <parent link="base_link"/>
    <child link="chassis"/>
  </joint>

  <link name="chassis">
    <visual>
      <origin xyz="0 0 0.05"/>
      <geometry>
        <box size="0.22 0.18 0.10"/>
      </geometry>
      <material name="black"/>
    </visual>
    <collision>
      <origin xyz="0 0 0.05"/>
      <geometry>
        <box size="0.22 0.18 0.10"/>
      </geometry>
    </collision>
    <xacro:inertial_box mass="1.5" x="0.22" y="0.18" z="0.10">
      <origin xyz="0 0 0.05"/>
    </xacro:inertial_box>
  </link>

    <!-- LEFT WHEEL -->
    <joint name="left_wheel_joint" type="continuous">
        <parent link="base_link"/>
        <child link="left_wheel"/>
        <origin xyz="0.0 0.09 0.035" rpy="0 0 0"/>
        <axis xyz="0 1 0"/>
    </joint>

    <link name="left_wheel">
        <visual>
            <origin xyz="0 0 0" rpy="0 0 0"/>
            <geometry>
                <cylinder radius="0.045" length="0.02"/>
            </geometry>
            <material name="black"/>
        </visual>
        <collision>
            <origin xyz="0 0 0" rpy="0 0 0"/>
            <geometry>
                <cylinder radius="0.045" length="0.02"/>
            </geometry>
        </collision>
        <xacro:inertial_cylinder mass="0.15" length="0.02" radius="0.045">
            <origin xyz="0 0 0" rpy="0 0 0"/>
        </xacro:inertial_cylinder>
    </link>


    <!-- RIGHT WHEEL -->
    <joint name="right_wheel_joint" type="continuous">
        <parent link="base_link"/>
        <child link="right_wheel"/>
        <origin xyz="0.0 -0.09 0.035" rpy="0 0 0"/>
        <axis xyz="0 1 0"/>
    </joint>

    <link name="right_wheel">
        <visual>
            <origin xyz="0 0 0" rpy="0 0 0"/>
            <geometry>
                <cylinder radius="0.045" length="0.02"/>
            </geometry>
            <material name="black"/>
        </visual>
        <collision>
            <origin xyz="0 0 0" rpy="0 0 0"/>
            <geometry>
                <cylinder radius="0.045" length="0.02"/>
            </geometry>
        </collision>
        <xacro:inertial_cylinder mass="0.15" length="0.02" radius="0.045">
            <origin xyz="0 0 0" rpy="0 0 0"/>
        </xacro:inertial_cylinder>
    </link>

  <!-- RPLidar -->
  <joint name="lidar_joint" type="fixed">
    <parent link="chassis"/>
    <child link="lidar"/>
    <origin xyz="0.07 0 0.1"/>
  </joint>

  <link name="lidar">
    <visual>
      <geometry>
        <cylinder radius="0.035" length="0.03"/>
      </geometry>
      <material name="silver"/>
    </visual>
    <collision>
      <geometry>
        <cylinder radius="0.035" length="0.03"/>
      </geometry>
    </collision>
    <xacro:inertial_cylinder mass="0.15" length="0.03" radius="0.035">
      <origin xyz="0 0 0"/>
    </xacro:inertial_cylinder>
  </link>

  <!-- Raspberry Pi camera -->
  <joint name="camera_joint" type="fixed">
    <parent link="chassis"/>
    <child link="camera"/>
    <origin xyz="0.05 0 0.1"/>
  </joint>

  <link name="camera">
    <visual>
      <geometry>
        <box size="0.025 0.025 0.02"/>
      </geometry>
      <material name="green"/>
    </visual>
    <xacro:inertial_box mass="0.05" x="0.025" y="0.025" z="0.02">
      <origin xyz="0 0 0"/>
    </xacro:inertial_box>
  </link>


</robot>
