<?xml version="1.0"?>
<robot xmlns:xacro="http://www.ros.org/wiki/xacro" name="xiaor_geek_bot">

  <!-- Include inertial macros -->
  <xacro:include filename="inertial_macros.xacro"/>

  <!-- Materials -->
    <material name="black"><color rgba="0 0 0 1"/></material>
    <material name="white"><color rgba="1 1 1 1"/></material>
    <material name="silver"><color rgba="0.75 0.75 0.75 1"/></material>
    <material name="blue"><color rgba="0.2 0.2 1 1"/></material>
    <material name="green"><color rgba="0.2 1 0.2 1"/></material>
    <material name="red"><color rgba="1 0.1 0.1 1"/></material>

    <!-- BASE LINK -->

    <link name="base_link">

    </link>


    <!-- CHASSIS LINK -->

    <joint name="chassis_joint" type="fixed">
        <parent link="base_link"/>
        <child link="chassis"/>
        <origin xyz="-0.1 0 0"/>
    </joint>

    <link name="chassis">
        <visual>
            <origin xyz="0.15 0 0.075"/>
            <geometry>
                <box size="0.3 0.3 0.15"/>
            </geometry>
            <material name="white"/>
        </visual>
        <collision>
            <origin xyz="0.15 0 0.075"/>
            <geometry>
                <box size="0.3 0.3 0.15"/>
            </geometry>
        </collision>
        <xacro:inertial_box mass="0.5" x="0.3" y="0.3" z="0.15">
            <origin xyz="0.15 0 0.075" rpy="0 0 0"/>
        </xacro:inertial_box>
    </link>
    
    <!-- LEFT WHEEL LINK -->

    <joint name="left_wheel_joint" type="continuous">
        <parent link="base_link"/>
        <child link="left_wheel"/>
        <origin xyz="0 0.175 0" rpy="-${pi/2} 0 0" />
        <axis xyz="0 0 1"/>
    </joint>

    <link name="left_wheel">
        <visual>
            <geometry>
                <cylinder radius="0.05" length="0.04"/>
            </geometry>
            <material name="blue"/>
        </visual>
        <collision>
            <geometry>
                <cylinder radius="0.05" length="0.04"/>
            </geometry>
        </collision>
        <xacro:inertial_cylinder mass="0.1" length="0.04" radius="0.05">
            <origin xyz="0 0 0" rpy="0 0 0"/>
        </xacro:inertial_cylinder>
    </link>

    <!-- RIGHT WHEEL LINK -->

    <joint name="right_wheel_joint" type="continuous">
        <parent link="base_link"/>
        <child link="right_wheel"/>
        <origin xyz="0 -0.175 0" rpy="${pi/2} 0 0" />
        <axis xyz="0 0 -1"/>
    </joint>

    <link name="right_wheel">
        <visual>
            <geometry>
                <cylinder radius="0.05" length="0.04"/>
            </geometry>
            <material name="blue"/>
        </visual>
        <collision>
            <geometry>
                <cylinder radius="0.05" length="0.04"/>
            </geometry>
        </collision>
        <xacro:inertial_cylinder mass="0.1" length="0.04" radius="0.05">
            <origin xyz="0 0 0" rpy="0 0 0"/>
        </xacro:inertial_cylinder>
    </link>

  <!-- RPLidar -->
  <joint name="lidar_joint" type="fixed">
    <parent link="chassis"/>
    <child link="lidar"/>
    <origin xyz="0.25 0 0.15"/>
  </joint>

  <link name="lidar">
    <visual>
      <geometry>
        <cylinder radius="0.035" length="0.03"/>
      </geometry>
      <material name="silver"/>
    </visual>
    <collision>
      <geometry>
        <cylinder radius="0.035" length="0.03"/>
      </geometry>
    </collision>
    <xacro:inertial_cylinder mass="0.15" length="0.03" radius="0.035">
      <origin xyz="0.25 0 0.15"/>
    </xacro:inertial_cylinder>
  </link>

  <!-- Raspberry Pi camera -->
  <joint name="camera_joint" type="fixed">
    <parent link="chassis"/>
    <child link="camera"/>
    <origin xyz="0.15 0 0.25"/>
  </joint>

  <link name="camera">
    <visual>
      <geometry>
        <box size="0.025 0.025 0.02"/>
      </geometry>
      <material name="green"/>
    </visual>
    <xacro:inertial_box mass="0.05" x="0.025" y="0.025" z="0.02">
      <origin xyz="0.15 0 0.25"/>
    </xacro:inertial_box>
  </link>
  
  <!-- CASTER WHEEL NO PURPOSE ONLY FOR SIMULATION AND GEOMETRY/PHYSICS -->
  
  <joint name="caster_wheel_joint" type="fixed">
    <parent link="chassis"/>
    <child link="caster_wheel"/>
    <origin xyz="0.24 0 0"/>
  </joint>

  <link name="caster_wheel">
      <visual>
          <geometry>
              <sphere radius="0.05"/>
          </geometry>
          <material name="black"/>
      </visual>
      <collision>
          <geometry>
              <sphere radius="0.05"/>
          </geometry>
      </collision>
      <xacro:inertial_sphere mass="0.1" radius="0.05">
          <origin xyz="0 0 0" rpy="0 0 0"/>
      </xacro:inertial_sphere>
  </link>

</robot>
